<?xml version="1.0" ?>
<sdf version="1.7">
  <model name="ball">

    <link name="sphere_link">
      <pose>0.0 0.0 0.05 0 0 0</pose>
      <visual name="visual3">
        <geometry>
          <sphere>
            <radius>0.05</radius>
          </sphere>
        </geometry>
      </visual>
      
      <collision name="collision3">
        <geometry>
          <sphere>
            <radius>0.05</radius>
          </sphere>
        </geometry>
      </collision>
      
      <inertial>
        <mass>10.0</mass>
        <inertia>
          <ixx>0.1</ixx>
          <ixy>0.0</ixy>
          <ixz>0.0</ixz>
          <iyy>0.1</iyy>
          <iyz>0.0</iyz>
          <izz>0.1</izz>
        </inertia>
      </inertial>
    </link>
    
    <link name="false_body1"/>

    <link name="false_body2"/>

    <joint name="weld_base" type="fixed">
      <child>false_body2</child>
      <parent>world</parent>
      <pose>0.0 0.5 0.05 0 0 0</pose>
    </joint>

    <joint name="prismatic_x_joint" type="prismatic">
      <child>false_body1</child>
      <parent>false_body2</parent>
      <axis>
        <xyz>1 0 0</xyz>
         <limit>
          <lower>-5.0</lower>
          <upper>5.0</upper>
          <velocity>1.0</velocity>
        </limit>
      </axis>
    </joint>

    <joint name="prismatic_y_joint" type="prismatic">
      <child>sphere_link</child>
      <parent>false_body1</parent>
      <axis>
        <xyz>0 1 0</xyz>
         <limit>
          <lower>-5.0</lower>
          <upper>5.0</upper>
          <velocity>1.0</velocity>
        </limit>
      </axis>
    </joint>
    
  </model>
</sdf>