<?xml version="1.0"?>
<sdf version="1.7">
  <model name="three_link_robot_arm">
    <link name="link1">
      <pose>0.0 0 0.05 1.57 0 1.57</pose>
      <inertial>
        <mass>1</mass>
        <inertia>
          <ixx>0.01455</ixx>
          <iyy>0.01455</iyy>
          <izz>1.041667e-05</izz>
          <ixy>0</ixy>
          <ixz>0</ixz>
          <iyz>0</iyz>
        </inertia>
      </inertial>
      <visual name="link1_visual">
        <geometry>
          <cylinder>
            <radius>0.025</radius>
            <length>0.15</length>
          </cylinder>
        </geometry>
        <material>
          <diffuse>1 0 0 1</diffuse>
        </material>
      </visual>
      <!-- using multiple collision spheres for collision geometry -->
      <collision name="link1_coll1">
        <geometry>
          <sphere>
            <radius>0.025</radius>
          </sphere>
        </geometry>
        <pose>0 0 0 0 0 0</pose>
      </collision>
      <collision name="link1_coll2">
        <geometry>
          <sphere>
            <radius>0.025</radius>
          </sphere>
        </geometry>
        <pose>0 0 -0.05 0 0 0</pose>
      </collision>
      <collision name="link1_coll3">
        <geometry>
          <sphere>
            <radius>0.025</radius>
          </sphere>
        </geometry>
        <pose>0 0 0.05 0 0 0</pose>
      </collision>
    </link>

    <joint name="joint1" type="revolute">
      <parent>world</parent>
      <child>link1</child>
      <axis>
        <xyz>0 1 0</xyz>
        <limit>
          <lower>-2.14159</lower>
          <upper>2.14159</upper>
          <effort>0</effort>
          <velocity>1.0</velocity>
        </limit>
        <dynamics>
          <damping>1.0</damping>
          <friction>1000.0</friction>
          <!-- <spring_stiffness>0.1</spring_stiffness> -->
        </dynamics>
      </axis>
      <pose>0 0 -0.1 0 0 0</pose>
    </joint>

    <link name="link2">
      <pose>0.225 0 0.05 1.57 0 1.57</pose>
      <inertial>
        <mass>1</mass>
        <inertia>
          <ixx>0.07275</ixx>
          <iyy>0.07275</iyy>
          <izz>1.041667e-05</izz>
          <ixy>0</ixy>
          <ixz>0</ixz>
          <iyz>0</iyz>
        </inertia>
      </inertial>
      <visual name="link2_visual">
        <geometry>
          <cylinder>
            <radius>0.025</radius>
            <length>0.3</length>
          </cylinder>
        </geometry>
        <material>
          <diffuse>0 1 0 1</diffuse>
        </material>
      </visual>
      <collision name="link2_collision1">
        <geometry>
          <sphere>
            <radius>0.025</radius>
          </sphere>
        </geometry>
      </collision>
      <collision name="link2_collision2">
        <geometry>
          <sphere>
            <radius>0.025</radius>
          </sphere>
        </geometry>
        <pose>0 0 -0.05 0 0 0</pose>
      </collision>
      <collision name="link2_collision3">
        <geometry>
          <sphere>
            <radius>0.025</radius>
          </sphere>
        </geometry>
        <pose>0 0 0.05 0 0 0</pose>
      </collision>
    </link>

    <joint name="joint2" type="revolute">
      <parent>link1</parent>
      <child>link2</child>
      <axis>
        <xyz>0 1 0</xyz>
        <limit>
          <lower>-2.14</lower>
          <upper>0.1</upper>
          <effort>0</effort>
          <velocity>1.0</velocity>
        </limit>
        <dynamics>
          <damping>1</damping>
          <friction>1000</friction>
        </dynamics>
      </axis>
      <pose>0.0 0 -0.15 0 0 0</pose>
    </joint>

    <link name="link3">
      <pose>0.45 0 0.05 1.57 0 1.57</pose>
      <inertial>
        <mass>1</mass>
        <inertia>
          <ixx>0.01455</ixx>
          <iyy>0.01455</iyy>
          <izz>1.041667e-05</izz>
          <ixy>0</ixy>
          <ixz>0</ixz>
          <iyz>0</iyz>
        </inertia>
      </inertial>
      <visual name="link3_visual">
        <geometry>
          <cylinder>
            <radius>0.025</radius>
            <length>0.15</length>
          </cylinder>
        </geometry>
        <material>
          <diffuse>0 0 1 1</diffuse>
        </material>
      </visual>
      <collision name="link3_coll1">
        <geometry>
          <sphere>
            <radius>0.025</radius>
          </sphere>
        </geometry>
        <pose>0 0 0 0 0 0</pose>
      </collision>
      <collision name="link3_coll2">
        <geometry>
          <sphere>
            <radius>0.025</radius>
          </sphere>
        </geometry>
        <pose>0 0 -0.05 0 0 0</pose>
      </collision>
      <collision name="link3_coll3">
        <geometry>
          <sphere>
            <radius>0.025</radius>
          </sphere>
        </geometry>
        <pose>0 0 0.05 0 0 0</pose>
      </collision>
    </link>

    <joint name="joint3" type="revolute">
      <parent>link2</parent>
      <child>link3</child>
      <axis>
        <xyz>0 1 0</xyz>
        <limit>
          <lower>-2.14159</lower>
          <upper>2.14159</upper>
          <effort>0</effort>
          <velocity>1.0</velocity>
        </limit>
        <dynamics>
          <damping>1</damping>
          <friction>1000</friction>
          <!-- <spring_stiffness>0.03</spring_stiffness> -->
        </dynamics>
      </axis>
      <pose>0 0 -0.1 0 0 0</pose>
    </joint>
  </model>
</sdf>