<?xml version="1.0" ?>
<sdf version="1.7">
  <model name="limb">
    <link name="limb_base">
      <pose>0.78 0.38 0.57 0 0 0</pose>
      <visual name="base_visual">
        <geometry>
          <cylinder>
            <radius>0.05</radius>
            <length>0.3</length>
          </cylinder>
        </geometry>
        <material>
          <diffuse>0.78 0.65 0.53 1</diffuse>
        </material>
      </visual>
    </link>
    <link name="link1">
      <pose>0.78 0.23 0.42 1.57 0 0</pose>
      <inertial>
        <mass>1</mass>
        <inertia>
          <ixx>0.01455</ixx>
          <iyy>0.01455</iyy>
          <izz>1.041667e-05</izz>
          <ixy>0</ixy>
          <ixz>0</ixz>
          <iyz>0</iyz>
        </inertia>
      </inertial>
      <visual name="link1_visual">
        <geometry>
          <cylinder>
            <radius>0.04</radius>
            <length>0.3</length>
          </cylinder>
        </geometry>
        <material>
          <diffuse>0.76 0.5 0.51 1</diffuse>
        </material>
      </visual>
      <!-- using multiple collision spheres for collision geometry -->
      <collision name="link1_coll1">
        <geometry>
          <sphere>
            <radius>0.041</radius>
          </sphere>
        </geometry>
        <drake:proximity_properties>
          <drake:compliant_hydroelastic/>
          <drake:hydroelastic_modulus>2.5e7</drake:hydroelastic_modulus>
          <drake:mesh_resolution_hint>0.01</drake:mesh_resolution_hint>
          <drake:mu_dynamic>1.0</drake:mu_dynamic>
          <drake:mu_static>1.0</drake:mu_static>
          <drake:hunt_crossley_dissipation>0.25</drake:hunt_crossley_dissipation>
        </drake:proximity_properties>
        <pose>0 0 0 0 0 0</pose>
      </collision>
      <collision name="link1_coll2">
        <geometry>
          <sphere>
            <radius>0.041</radius>
          </sphere>
        </geometry>
        <drake:proximity_properties>
          <drake:compliant_hydroelastic/>
          <drake:hydroelastic_modulus>2.5e7</drake:hydroelastic_modulus>
          <drake:mesh_resolution_hint>0.01</drake:mesh_resolution_hint>
          <drake:mu_dynamic>1.0</drake:mu_dynamic>
          <drake:mu_static>1.0</drake:mu_static>
          <drake:hunt_crossley_dissipation>0.25</drake:hunt_crossley_dissipation>
        </drake:proximity_properties>
        <pose>0 0 -0.05 0 0 0</pose>
      </collision>
      <collision name="link1_coll3">
        <geometry>
          <sphere>
            <radius>0.041</radius>
          </sphere>
        </geometry>
        <drake:proximity_properties>
          <drake:compliant_hydroelastic/>
          <drake:hydroelastic_modulus>2.5e7</drake:hydroelastic_modulus>
          <drake:mesh_resolution_hint>0.01</drake:mesh_resolution_hint>
          <drake:mu_dynamic>1.0</drake:mu_dynamic>
          <drake:mu_static>1.0</drake:mu_static>
          <drake:hunt_crossley_dissipation>0.25</drake:hunt_crossley_dissipation>
        </drake:proximity_properties>
        <pose>0 0 0.05 0 0 0</pose>
      </collision>
      <collision name="link1_coll5">
        <geometry>
          <sphere>
            <radius>0.041</radius>
          </sphere>
        </geometry>
        <drake:proximity_properties>
          <drake:compliant_hydroelastic/>
          <drake:hydroelastic_modulus>2.5e7</drake:hydroelastic_modulus>
          <drake:mesh_resolution_hint>0.01</drake:mesh_resolution_hint>
          <drake:mu_dynamic>1.0</drake:mu_dynamic>
          <drake:mu_static>1.0</drake:mu_static>
          <drake:hunt_crossley_dissipation>0.25</drake:hunt_crossley_dissipation>
        </drake:proximity_properties>
        <pose>0 0 0.10 0 0 0</pose>
      </collision>
      <collision name="link1_coll6">
        <geometry>
          <sphere>
            <radius>0.041</radius>
          </sphere>
        </geometry>
        <drake:proximity_properties>
          <drake:compliant_hydroelastic/>
          <drake:hydroelastic_modulus>2.5e7</drake:hydroelastic_modulus>
          <drake:mesh_resolution_hint>0.01</drake:mesh_resolution_hint>
          <drake:mu_dynamic>1.0</drake:mu_dynamic>
          <drake:mu_static>1.0</drake:mu_static>
          <drake:hunt_crossley_dissipation>0.25</drake:hunt_crossley_dissipation>
        </drake:proximity_properties>
        <pose>0 0 -0.10 0 0 0</pose>
      </collision>
    </link>
    <joint name="joint1" type="revolute">
      <parent>limb_base</parent>
      <child>link1</child>
      <axis>
        <xyz>1 0 0</xyz>
        <limit>
          <lower>-2.14159</lower>
          <upper>2.14159</upper>
          <effort>0</effort>
          <velocity>1.0</velocity>
        </limit>
        <dynamics>
          <damping>1.0</damping>
          <friction>1000.0</friction>
          <!-- <spring_stiffness>0.1</spring_stiffness> -->
        </dynamics>
      </axis>
      <pose>0 0 -0.075 0 0 0</pose>
    </joint>
    <link name="link2">
      <pose>0.78 -0.07 0.42 1.57 0 0</pose>
      <inertial>
        <mass>1</mass>
        <inertia>
          <ixx>0.07275</ixx>
          <iyy>0.07275</iyy>
          <izz>1.041667e-05</izz>
          <ixy>0</ixy>
          <ixz>0</ixz>
          <iyz>0</iyz>
        </inertia>
      </inertial>
      <visual name="link2_visual">
        <geometry>
          <cylinder>
            <radius>0.04</radius>
            <length>0.3</length>
          </cylinder>
        </geometry>
        <material>
          <diffuse>0.76 0.64 0.51 1</diffuse>
        </material>
      </visual>
      <collision name="link2_collision1">
        <geometry>
          <sphere>
            <radius>0.04</radius>
          </sphere>
        </geometry>
        <drake:proximity_properties>
          <drake:compliant_hydroelastic/>
          <drake:hydroelastic_modulus>2.5e7</drake:hydroelastic_modulus>
          <drake:mesh_resolution_hint>0.01</drake:mesh_resolution_hint>
          <drake:mu_dynamic>1.0</drake:mu_dynamic>
          <drake:mu_static>1.0</drake:mu_static>
          <drake:hunt_crossley_dissipation>0.25</drake:hunt_crossley_dissipation>
        </drake:proximity_properties>
      </collision>
      <collision name="link2_collision2">
        <geometry>
          <sphere>
            <radius>0.04</radius>
          </sphere>
        </geometry>
        <drake:proximity_properties>
          <drake:compliant_hydroelastic/>
          <drake:hydroelastic_modulus>2.5e7</drake:hydroelastic_modulus>
          <drake:mesh_resolution_hint>0.01</drake:mesh_resolution_hint>
          <drake:mu_dynamic>1.0</drake:mu_dynamic>
          <drake:mu_static>1.0</drake:mu_static>
          <drake:hunt_crossley_dissipation>0.25</drake:hunt_crossley_dissipation>
        </drake:proximity_properties>
        <pose>0 0 -0.05 0 0 0</pose>
      </collision>
      <collision name="link2_collision3">
        <geometry>
          <sphere>
            <radius>0.04</radius>
          </sphere>
        </geometry>
        <drake:proximity_properties>
          <drake:compliant_hydroelastic/>
          <drake:hydroelastic_modulus>2.5e7</drake:hydroelastic_modulus>
          <drake:mesh_resolution_hint>0.01</drake:mesh_resolution_hint>
          <drake:mu_dynamic>1.0</drake:mu_dynamic>
          <drake:mu_static>1.0</drake:mu_static>
          <drake:hunt_crossley_dissipation>0.25</drake:hunt_crossley_dissipation>
        </drake:proximity_properties>
        <pose>0 0 0.05 0 0 0</pose>
      </collision>
      <collision name="link2_collision5">
        <geometry>
          <sphere>
            <radius>0.04</radius>
          </sphere>
        </geometry>
        <drake:proximity_properties>
          <drake:compliant_hydroelastic/>
          <drake:hydroelastic_modulus>2.5e7</drake:hydroelastic_modulus>
          <drake:mesh_resolution_hint>0.01</drake:mesh_resolution_hint>
          <drake:mu_dynamic>1.0</drake:mu_dynamic>
          <drake:mu_static>1.0</drake:mu_static>
          <drake:hunt_crossley_dissipation>0.25</drake:hunt_crossley_dissipation>
        </drake:proximity_properties>
        <pose>0 0 0.10 0 0 0</pose>
      </collision>
      <collision name="link2_collision6">
        <geometry>
          <sphere>
            <radius>0.04</radius>
          </sphere>
        </geometry>
        <drake:proximity_properties>
          <drake:compliant_hydroelastic/>
          <drake:hydroelastic_modulus>2.5e7</drake:hydroelastic_modulus>
          <drake:mesh_resolution_hint>0.01</drake:mesh_resolution_hint>
          <drake:mu_dynamic>1.0</drake:mu_dynamic>
          <drake:mu_static>1.0</drake:mu_static>
          <drake:hunt_crossley_dissipation>0.25</drake:hunt_crossley_dissipation>
        </drake:proximity_properties>
        <pose>0 0 -0.10 0 0 0</pose>
      </collision>
      <collision name="link2_collision7">
        <geometry>
          <sphere>
            <radius>0.04</radius>
          </sphere>
        </geometry>
        <drake:proximity_properties>
          <drake:compliant_hydroelastic/>
          <drake:hydroelastic_modulus>2.5e7</drake:hydroelastic_modulus>
          <drake:mesh_resolution_hint>0.01</drake:mesh_resolution_hint>
          <drake:mu_dynamic>1.0</drake:mu_dynamic>
          <drake:mu_static>1.0</drake:mu_static>
          <drake:hunt_crossley_dissipation>0.25</drake:hunt_crossley_dissipation>
        </drake:proximity_properties>
        <pose>0 0 -0.15 0 0 0</pose>
      </collision>
    </link>

    <joint name="joint2" type="revolute">
      <parent>link1</parent>
      <child>link2</child>
      <axis>
        <xyz>1 0 0</xyz>
        <limit>
          <lower>-0.2</lower>
          <upper>2.14</upper>
          <effort>0</effort>
          <velocity>1.0</velocity>
        </limit>
        <dynamics>
          <damping>1</damping>
          <friction>1000</friction>
        </dynamics>
      </axis>
      <pose>0.0 0 -0.15 0 0 0</pose>
    </joint>
  </model>
</sdf>